Workbook

Sheet Configuration
B2: Configuration - Housekeeping Room Attendant Scheduling Tool
B4: Hotel name | C4: Example
B5: Number of rooms | C5: =C14 -> 255
B6: Shift Lenght (hours) | C6: 8
B8: Value of Rooms (credits)
B9: Room Type | C9: Number of Rooms | D9: # of Credits | E9: Total Credits
B10: Type 1 | C10: 120 | D10: 1 | E10: =C10*D10 -> 120
B11: Type 2 | C11: 85 | D11: 1.5 | E11: =C11*D11 -> 127.5
B12: Type 3 | C12: 45 | D12: 2 | E12: =C12*D12 -> 90
B13: Type 4 | C13: 5 | D13: 3 | E13: =C13*D13 -> 15
B14: Total | C14: =SUM(C10:C13) -> 255 | E14: =SUM(E10:E13) -> 352.5
B15: Average Credit / Room | E15: =E14/C14 -> 1.3823529
B17: Departures Drop Rules (as per the contract)
B18: Rule # | C18: Departures | D18: Max Credits to clean | E18: Description
B19: Rule 1 | D19: 13 | E19: Maximum of 13 credits at all time
B20: Rule 2 | C20: 8 | D20: 12 | E20: If 8 departures or more, drop 1 credit
B21: Rule 3 | C21: 9 | D21: 11 | E21: If 9 departures or more, drop 2 credits
B22: Rule 4 | C22: 10 | D22: 10 | E22: If 10 departures or more, drop 3 credits
B24: In this example, the value of a Departure and a Stayover is the same, and the hotel does not offer Turndown service. If needed, a personalized dashboard can be built on your specific hotel needs.

Sheet Weekly Schedule
B2: Weekly Schedule - Housekeeping Room Attendant Scheduling Tool
B4: Statistics
B5: Date | C5: 46117 | D5: =C5+1 -> 46118 | E5: =D5+1 -> 46119 | F5: =E5+1 -> 46120 | G5: =F5+1 -> 46121 | H5: =G5+1 -> 46122 | I5: =H5+1 -> 46123
B6: Weekday | C6: =TEXT(WEEKDAY(C5,1),"dddd") -> Sunday | D6: =TEXT(WEEKDAY(D5,1),"dddd") -> Monday | E6: =TEXT(WEEKDAY(E5,1),"dddd") -> Tuesday | F6: =TEXT(WEEKDAY(F5,1),"dddd") -> Wednesday | G6: =TEXT(WEEKDAY(G5,1),"dddd") -> Thursday | H6: =TEXT(WEEKDAY(H5,1),"dddd") -> Friday | I6: =TEXT(WEEKDAY(I5,1),"dddd") -> Saturday | J6: Total | L6: Notes
B7: Forecasted Volumes
B8: Occupied Rooms | C8: 110 | D8: =C8-C10+C9 -> 95 | E8: =D8-D10+D9 -> 125 | F8: =E8-E10+E9 -> 152 | G8: =F8-F10+F9 -> 165 | H8: =G8-G10+G9 -> 189 | I8: =H8-H10+H9 -> 248 | J8: =SUM(C8:I8) -> 1084
B9: Arrivals | C9: 85 | D9: 50 | E9: 75 | F9: 55 | G9: 65 | H9: 115 | I9: 90 | J9: =SUM(C9:I9) -> 535
B10: Departures | C10: 100 | D10: 20 | E10: 48 | F10: 42 | G10: 41 | H10: 56 | I10: 94 | J10: =SUM(C10:I10) -> 401 | L10: In this example, we only consider Departures, Rooms to Carry or Carried Over, and Stayovers, but a personalized example could also consider rooms to clean that were out of order, expected room moves, etc.
B11: Rooms Carried Over (from yesterday) | C11: 75 | D11: =C12 -> 20 | E11: =D12 -> 0 | F11: =E12 -> 5 | G11: =F12 -> 0 | H11: =G12 -> 10 | I11: =H12 -> 0 | J11: =SUM(C11:I11) -> 110
B12: Rooms to Carry Over (to tomorrow) | C12: 20 | E12: 5 | G12: 10 | J12: =SUM(C12:I12) -> 35
B13: Stayovers (calculated) | C13: =C8-C9 -> 25 | D13: =D8-D9 -> 45 | E13: =E8-E9 -> 50 | F13: =F8-F9 -> 97 | G13: =G8-G9 -> 100 | H13: =H8-H9 -> 74 | I13: =I8-I9 -> 158 | J13: =SUM(C13:I13) -> 549 | L13: Stayovers can be calculated as (Last Night Occupied Rooms - Today's Departures) or (Today's Occupied Rooms - Today's Arrivals)
B14: DND and RS % | C14: 0.15 | D14: 0.22 | E14: 0.23 | F14: 0.24 | G14: 0.24 | H14: 0.21 | I14: 0.12 | L14: In this example, the DND and Refused Service (RS) is hard coded, but ideally it should be a forecast based on historical information
B15: DND and RS # (calculated) | C15: =C14*C13 -> 3.75 | D15: =D14*D13 -> 9.9 | E15: =E14*E13 -> 11.5 | F15: =F14*F13 -> 23.28 | G15: =G14*G13 -> 24 | H15: =H14*H13 -> 15.54 | I15: =I14*I13 -> 18.96 | J15: =SUM(C15:I15) -> 106.93
B16: Additional Credits Drop | C16: 1 | D16: 3 | E16: 3 | F16: 2 | G16: 1 | H16: 0 | I16: 4 | J16: =SUM(C16:I16) -> 14 | L16: In this example, we only have one line for additional credits dropped (ex. travel credits, multiple beds, etc.), but a personalized example could plan for the individual credits to drop
B18: Calculation
B19: Date | C19: =C5 -> 46117 | D19: =D5 -> 46118 | E19: =E5 -> 46119 | F19: =F5 -> 46120 | G19: =G5 -> 46121 | H19: =H5 -> 46122 | I19: =I5 -> 46123
B20: Weekday | C20: =TEXT(WEEKDAY(C19,1),"dddd") -> Sunday | D20: =TEXT(WEEKDAY(D19,1),"dddd") -> Monday | E20: =TEXT(WEEKDAY(E19,1),"dddd") -> Tuesday | F20: =TEXT(WEEKDAY(F19,1),"dddd") -> Wednesday | G20: =TEXT(WEEKDAY(G19,1),"dddd") -> Thursday | H20: =TEXT(WEEKDAY(H19,1),"dddd") -> Friday | I20: =TEXT(WEEKDAY(I19,1),"dddd") -> Saturday | J20: Total | L20: Notes
B21: Rooms Statistics
B22: Departures to clean | C22: =C10-C12+C11 -> 155 | D22: =D10-D12+D11 -> 40 | E22: =E10-E12+E11 -> 43 | F22: =F10-F12+F11 -> 47 | G22: =G10-G12+G11 -> 31 | H22: =H10-H12+H11 -> 66 | I22: =I10-I12+I11 -> 94 | J22: =SUM(C22:I22) -> 476 | L22: Departures to clean are calculated as : Departures of the day + Rooms Carried Over from Yesterday - Rooms to Carry Over to Tomorrow
B23: Stayovers to clean | C23: =C13-C15 -> 21.25 | D23: =D13-D15 -> 35.1 | E23: =E13-E15 -> 38.5 | F23: =F13-F15 -> 73.72 | G23: =G13-G15 -> 76 | H23: =H13-H15 -> 58.46 | I23: =I13-I15 -> 139.04 | J23: =SUM(C23:I23) -> 442.07 | L23: Stayovers to clean are calculated as : Stayovers - expected DND and RS rooms
B24: Total Rooms to clean | C24: =SUM(C22:C23) -> 176.25 | D24: =SUM(D22:D23) -> 75.1 | E24: =SUM(E22:E23) -> 81.5 | F24: =SUM(F22:F23) -> 120.72 | G24: =SUM(G22:G23) -> 107 | H24: =SUM(H22:H23) -> 124.46 | I24: =SUM(I22:I23) -> 233.04 | J24: =SUM(C24:I24) -> 918.07
B25: Calculated Credits to clean
B26: Estimated Credits to clean | C26: =C24*Configuration!$E$15 -> 243.63971 | D26: =D24*Configuration!$E$15 -> 103.81471 | E26: =E24*Configuration!$E$15 -> 112.66176 | F26: =F24*Configuration!$E$15 -> 166.87765 | G26: =G24*Configuration!$E$15 -> 147.91176 | H26: =H24*Configuration!$E$15 -> 172.04765 | I26: =I24*Configuration!$E$15 -> 322.14353 | J26: =SUM(C26:I26) -> 1269.0968
B27: Additional Credits to Drop | C27: =C16 -> 1 | D27: =D16 -> 3 | E27: =E16 -> 3 | F27: =F16 -> 2 | G27: =G16 -> 1 | H27: =H16 -> 0 | I27: =I16 -> 4 | J27: =SUM(C27:I27) -> 14
B28: Total Credits to consider | C28: =SUM(C26:C27) -> 244.63971 | D28: =SUM(D26:D27) -> 106.81471 | E28: =SUM(E26:E27) -> 115.66176 | F28: =SUM(F26:F27) -> 168.87765 | G28: =SUM(G26:G27) -> 148.91176 | H28: =SUM(H26:H27) -> 172.04765 | I28: =SUM(I26:I27) -> 326.14353 | J28: =SUM(C28:I28) -> 1283.0968
B29: Room Attendants to schedule
B30: First Rule (Maximum Credit Attainment) | L30: In this calculation, we apply the first rule of the contract (at a maximum, a Room Attendant can clean X credits)
B31: # of Room Attendant | C31: =ROUNDUP(C$28/Configuration!$D$19,0) -> 19 | D31: =ROUNDUP(D$28/Configuration!$D$19,0) -> 9 | E31: =ROUNDUP(E$28/Configuration!$D$19,0) -> 9 | F31: =ROUNDUP(F$28/Configuration!$D$19,0) -> 13 | G31: =ROUNDUP(G$28/Configuration!$D$19,0) -> 12 | H31: =ROUNDUP(H$28/Configuration!$D$19,0) -> 14 | I31: =ROUNDUP(I$28/Configuration!$D$19,0) -> 26 | J31: =SUM(C31:I31) -> 102
B32: Average # of Departures / Room Attendant | C32: =IFERROR(C22/C31,"") -> 8.1578947 | D32: =IFERROR(D22/D31,"") -> 4.4444444 | E32: =IFERROR(E22/E31,"") -> 4.7777778 | F32: =IFERROR(F22/F31,"") -> 3.6153846 | G32: =IFERROR(G22/G31,"") -> 2.5833333 | H32: =IFERROR(H22/H31,"") -> 4.7142857 | I32: =IFERROR(I22/I31,"") -> 3.6153846 | J32: =SUM(C32:I32) -> 31.908505
B33: Second Rule
B34: # of Room Attendant | C34: =ROUNDUP(IF(C$32>=Configuration!$C$20,'Weekly Schedule'!C$28/Configuration!$D$20,C$31),0) -> 21 | D34: =ROUNDUP(IF(D$32>=Configuration!$C$20,'Weekly Schedule'!D$28/Configuration!$D$20,D$31),0) -> 9 | E34: =ROUNDUP(IF(E$32>=Configuration!$C$20,'Weekly Schedule'!E$28/Configuration!$D$20,E$31),0) -> 9 | F34: =ROUNDUP(IF(F$32>=Configuration!$C$20,'Weekly Schedule'!F$28/Configuration!$D$20,F$31),0) -> 13 | G34: =ROUNDUP(IF(G$32>=Configuration!$C$20,'Weekly Schedule'!G$28/Configuration!$D$20,G$31),0) -> 12 | H34: =ROUNDUP(IF(H$32>=Configuration!$C$20,'Weekly Schedule'!H$28/Configuration!$D$20,H$31),0) -> 14 | I34: =ROUNDUP(IF(I$32>=Configuration!$C$20,'Weekly Schedule'!I$28/Configuration!$D$20,I$31),0) -> 26 | J34: =SUM(C34:I34) -> 104 | L34: If the number of departures from the Rule 1 section is more than the what the second Rule is suggesting, this row is suggesting to then apply the maximum credits suggested by Rule 2 instead of Rule 1.
B35: Average # of Departures / Room Attendant | C35: =IFERROR(C22/C34,"") -> 7.3809524 | D35: =IFERROR(D22/D34,"") -> 4.4444444 | E35: =IFERROR(E22/E34,"") -> 4.7777778 | F35: =IFERROR(F22/F34,"") -> 3.6153846 | G35: =IFERROR(G22/G34,"") -> 2.5833333 | H35: =IFERROR(H22/H34,"") -> 4.7142857 | I35: =IFERROR(I22/I34,"") -> 3.6153846 | J35: =SUM(C35:I35) -> 31.131563
B36: Third Rule
B37: # of Room Attendant | C37: =ROUNDUP(IF(C$35>=Configuration!$C$21,'Weekly Schedule'!C$28/Configuration!$D$21,C$34),0) -> 21 | D37: =ROUNDUP(IF(D$35>=Configuration!$C$21,'Weekly Schedule'!D$28/Configuration!$D$21,D$34),0) -> 9 | E37: =ROUNDUP(IF(E$35>=Configuration!$C$21,'Weekly Schedule'!E$28/Configuration!$D$21,E$34),0) -> 9 | F37: =ROUNDUP(IF(F$35>=Configuration!$C$21,'Weekly Schedule'!F$28/Configuration!$D$21,F$34),0) -> 13 | G37: =ROUNDUP(IF(G$35>=Configuration!$C$21,'Weekly Schedule'!G$28/Configuration!$D$21,G$34),0) -> 12 | H37: =ROUNDUP(IF(H$35>=Configuration!$C$21,'Weekly Schedule'!H$28/Configuration!$D$21,H$34),0) -> 14 | I37: =ROUNDUP(IF(I$35>=Configuration!$C$21,'Weekly Schedule'!I$28/Configuration!$D$21,I$34),0) -> 26 | J37: =SUM(C37:I37) -> 104 | L37: If the number of departures from the Rule 2 section is more than the what the third Rule is suggesting, this row is suggesting to then apply the maximum credits suggested by Rule 3 instead of Rule 2.
B38: Average # of Departures / Room Attendant | C38: =IFERROR(C$22/C$37,"") -> 7.3809524 | D38: =IFERROR(D$22/D$37,"") -> 4.4444444 | E38: =IFERROR(E$22/E$37,"") -> 4.7777778 | F38: =IFERROR(F$22/F$37,"") -> 3.6153846 | G38: =IFERROR(G$22/G$37,"") -> 2.5833333 | H38: =IFERROR(H$22/H$37,"") -> 4.7142857 | I38: =IFERROR(I$22/I$37,"") -> 3.6153846 | J38: =SUM(C38:I38) -> 31.131563
B39: Fourth Rule
B40: # of Room Attendant | C40: =ROUNDUP(IF(C$38>=Configuration!$C$22,'Weekly Schedule'!C$24/Configuration!$D$22,C$37),0) -> 21 | D40: =ROUNDUP(IF(D$38>=Configuration!$C$22,'Weekly Schedule'!D$24/Configuration!$D$22,D$37),0) -> 9 | E40: =ROUNDUP(IF(E$38>=Configuration!$C$22,'Weekly Schedule'!E$24/Configuration!$D$22,E$37),0) -> 9 | F40: =ROUNDUP(IF(F$38>=Configuration!$C$22,'Weekly Schedule'!F$24/Configuration!$D$22,F$37),0) -> 13 | G40: =ROUNDUP(IF(G$38>=Configuration!$C$22,'Weekly Schedule'!G$24/Configuration!$D$22,G$37),0) -> 12 | H40: =ROUNDUP(IF(H$38>=Configuration!$C$22,'Weekly Schedule'!H$24/Configuration!$D$22,H$37),0) -> 14 | I40: =ROUNDUP(IF(I$38>=Configuration!$C$22,'Weekly Schedule'!I$24/Configuration!$D$22,I$37),0) -> 26 | J40: =SUM(C40:I40) -> 104 | L40: If the number of departures from the Rule 3 section is more than the what the fourth Rule is suggesting, this row is suggesting to then apply the maximum credits suggested by Rule 4 instead of Rule 3.
B41: Average # of Departures / Room Attendant | C41: =IFERROR(C22/C40,"") -> 7.3809524 | D41: =IFERROR(D22/D40,"") -> 4.4444444 | E41: =IFERROR(E22/E40,"") -> 4.7777778 | F41: =IFERROR(F22/F40,"") -> 3.6153846 | G41: =IFERROR(G22/G40,"") -> 2.5833333 | H41: =IFERROR(H22/H40,"") -> 4.7142857 | I41: =IFERROR(I22/I40,"") -> 3.6153846 | J41: =SUM(C41:I41) -> 31.131563
B42: Total Room Attendants to schedule | C42: =C40 -> 21 | D42: =D40 -> 9 | E42: =E40 -> 9 | F42: =F40 -> 13 | G42: =G40 -> 12 | H42: =H40 -> 14 | I42: =I40 -> 26 | J42: =SUM(C42:I42) -> 104 | L42: This row tells you the total number of Room Attendants to schedule to clean all your expected rooms to clean (Departures, Rooms Carried Over, and Stayovers)
B43: Potential Credit Attainment | C43: =IFERROR(C26/C42,"") -> 11.601891 | D43: =IFERROR(D26/D42,"") -> 11.534967 | E43: =IFERROR(E26/E42,"") -> 12.517974 | F43: =IFERROR(F26/F42,"") -> 12.836742 | G43: =IFERROR(G26/G42,"") -> 12.32598 | H43: =IFERROR(H26/H42,"") -> 12.289118 | I43: =IFERROR(I26/I42,"") -> 12.390136 | J43: =SUM(C43:I43) -> 85.496808 | L43: This row tells you the potential Credits Attained / Room Attendant. Realistically, if your Forecasted stats are representative of your Actual stats, and that you follow your contract rules, then this is the maximum Credits Attainment / Room Attendant you could expect to achieve.
...
